[2023-06-16T01:01:29.161+0000] {taskinstance.py:1084} INFO - Dependencies all met for dep_context=non-requeueable deps ti=<TaskInstance: data_ingestion_gcs_dag.local_to_gcs_task manual__2023-06-16T01:00:17.602002+00:00 [queued]>
[2023-06-16T01:01:29.175+0000] {taskinstance.py:1084} INFO - Dependencies all met for dep_context=requeueable deps ti=<TaskInstance: data_ingestion_gcs_dag.local_to_gcs_task manual__2023-06-16T01:00:17.602002+00:00 [queued]>
[2023-06-16T01:01:29.177+0000] {taskinstance.py:1282} INFO - 
--------------------------------------------------------------------------------
[2023-06-16T01:01:29.178+0000] {taskinstance.py:1283} INFO - Starting attempt 1 of 2
[2023-06-16T01:01:29.179+0000] {taskinstance.py:1284} INFO - 
--------------------------------------------------------------------------------
[2023-06-16T01:01:29.199+0000] {taskinstance.py:1303} INFO - Executing <Task(PythonOperator): local_to_gcs_task> on 2023-06-16 01:00:17.602002+00:00
[2023-06-16T01:01:29.209+0000] {standard_task_runner.py:55} INFO - Started process 1796 to run task
[2023-06-16T01:01:29.212+0000] {standard_task_runner.py:82} INFO - Running: ['***', 'tasks', 'run', 'data_ingestion_gcs_dag', 'local_to_gcs_task', 'manual__2023-06-16T01:00:17.602002+00:00', '--job-id', '519', '--raw', '--subdir', 'DAGS_FOLDER/data_ingestion_gcs_dag.py', '--cfg-path', '/tmp/tmp5u5e_f25']
[2023-06-16T01:01:29.217+0000] {standard_task_runner.py:83} INFO - Job 519: Subtask local_to_gcs_task
[2023-06-16T01:01:29.319+0000] {task_command.py:388} INFO - Running <TaskInstance: data_ingestion_gcs_dag.local_to_gcs_task manual__2023-06-16T01:00:17.602002+00:00 [running]> on host 2a315e4d94ac
[2023-06-16T01:01:29.414+0000] {taskinstance.py:1511} INFO - Exporting the following env vars:
AIRFLOW_CTX_DAG_OWNER=***
AIRFLOW_CTX_DAG_ID=data_ingestion_gcs_dag
AIRFLOW_CTX_TASK_ID=local_to_gcs_task
AIRFLOW_CTX_EXECUTION_DATE=2023-06-16T01:00:17.602002+00:00
AIRFLOW_CTX_TRY_NUMBER=1
AIRFLOW_CTX_DAG_RUN_ID=manual__2023-06-16T01:00:17.602002+00:00
[2023-06-16T01:01:29.909+0000] {taskinstance.py:1775} ERROR - Task failed with exception
Traceback (most recent call last):
  File "/home/airflow/.local/lib/python3.7/site-packages/urllib3/connectionpool.py", line 710, in urlopen
    chunked=chunked,
  File "/home/airflow/.local/lib/python3.7/site-packages/urllib3/connectionpool.py", line 386, in _make_request
    self._validate_conn(conn)
  File "/home/airflow/.local/lib/python3.7/site-packages/urllib3/connectionpool.py", line 1042, in _validate_conn
    conn.connect()
  File "/home/airflow/.local/lib/python3.7/site-packages/urllib3/connection.py", line 429, in connect
    tls_in_tls=tls_in_tls,
  File "/home/airflow/.local/lib/python3.7/site-packages/urllib3/util/ssl_.py", line 450, in ssl_wrap_socket
    sock, context, tls_in_tls, server_hostname=server_hostname
  File "/home/airflow/.local/lib/python3.7/site-packages/urllib3/util/ssl_.py", line 493, in _ssl_wrap_socket_impl
    return ssl_context.wrap_socket(sock, server_hostname=server_hostname)
  File "/usr/local/lib/python3.7/ssl.py", line 423, in wrap_socket
    session=session
  File "/usr/local/lib/python3.7/ssl.py", line 870, in _create
    self.do_handshake()
  File "/usr/local/lib/python3.7/ssl.py", line 1139, in do_handshake
    self._sslobj.do_handshake()
OSError: [Errno 0] Error

During handling of the above exception, another exception occurred:

Traceback (most recent call last):
  File "/home/airflow/.local/lib/python3.7/site-packages/requests/adapters.py", line 499, in send
    timeout=timeout,
  File "/home/airflow/.local/lib/python3.7/site-packages/urllib3/connectionpool.py", line 788, in urlopen
    method, url, error=e, _pool=self, _stacktrace=sys.exc_info()[2]
  File "/home/airflow/.local/lib/python3.7/site-packages/urllib3/util/retry.py", line 550, in increment
    raise six.reraise(type(error), error, _stacktrace)
  File "/home/airflow/.local/lib/python3.7/site-packages/urllib3/packages/six.py", line 769, in reraise
    raise value.with_traceback(tb)
  File "/home/airflow/.local/lib/python3.7/site-packages/urllib3/connectionpool.py", line 710, in urlopen
    chunked=chunked,
  File "/home/airflow/.local/lib/python3.7/site-packages/urllib3/connectionpool.py", line 386, in _make_request
    self._validate_conn(conn)
  File "/home/airflow/.local/lib/python3.7/site-packages/urllib3/connectionpool.py", line 1042, in _validate_conn
    conn.connect()
  File "/home/airflow/.local/lib/python3.7/site-packages/urllib3/connection.py", line 429, in connect
    tls_in_tls=tls_in_tls,
  File "/home/airflow/.local/lib/python3.7/site-packages/urllib3/util/ssl_.py", line 450, in ssl_wrap_socket
    sock, context, tls_in_tls, server_hostname=server_hostname
  File "/home/airflow/.local/lib/python3.7/site-packages/urllib3/util/ssl_.py", line 493, in _ssl_wrap_socket_impl
    return ssl_context.wrap_socket(sock, server_hostname=server_hostname)
  File "/usr/local/lib/python3.7/ssl.py", line 423, in wrap_socket
    session=session
  File "/usr/local/lib/python3.7/ssl.py", line 870, in _create
    self.do_handshake()
  File "/usr/local/lib/python3.7/ssl.py", line 1139, in do_handshake
    self._sslobj.do_handshake()
urllib3.exceptions.ProtocolError: ('Connection aborted.', OSError(0, 'Error'))

During handling of the above exception, another exception occurred:

Traceback (most recent call last):
  File "/home/airflow/.local/lib/python3.7/site-packages/google/auth/transport/requests.py", line 194, in __call__
    method, url, data=body, headers=headers, timeout=timeout, **kwargs
  File "/home/airflow/.local/lib/python3.7/site-packages/requests/sessions.py", line 587, in request
    resp = self.send(prep, **send_kwargs)
  File "/home/airflow/.local/lib/python3.7/site-packages/requests/sessions.py", line 701, in send
    r = adapter.send(request, **kwargs)
  File "/home/airflow/.local/lib/python3.7/site-packages/requests/adapters.py", line 547, in send
    raise ConnectionError(err, request=request)
requests.exceptions.ConnectionError: ('Connection aborted.', OSError(0, 'Error'))

The above exception was the direct cause of the following exception:

Traceback (most recent call last):
  File "/home/airflow/.local/lib/python3.7/site-packages/airflow/operators/python.py", line 175, in execute
    return_value = self.execute_callable()
  File "/home/airflow/.local/lib/python3.7/site-packages/airflow/operators/python.py", line 192, in execute_callable
    return self.python_callable(*self.op_args, **self.op_kwargs)
  File "/opt/airflow/dags/data_ingestion_gcs_dag.py", line 47, in upload_to_gcs
    blob.upload_from_filename(file_path)
  File "/home/airflow/.local/lib/python3.7/site-packages/google/cloud/storage/blob.py", line 2696, in upload_from_filename
    retry=retry,
  File "/home/airflow/.local/lib/python3.7/site-packages/google/cloud/storage/blob.py", line 2552, in upload_from_file
    retry=retry,
  File "/home/airflow/.local/lib/python3.7/site-packages/google/cloud/storage/blob.py", line 2367, in _do_upload
    retry=retry,
  File "/home/airflow/.local/lib/python3.7/site-packages/google/cloud/storage/blob.py", line 1890, in _do_multipart_upload
    transport, data, object_metadata, content_type, timeout=timeout
  File "/home/airflow/.local/lib/python3.7/site-packages/google/resumable_media/requests/upload.py", line 154, in transmit
    retriable_request, self._get_status_code, self._retry_strategy
  File "/home/airflow/.local/lib/python3.7/site-packages/google/resumable_media/requests/_request_helpers.py", line 148, in wait_and_retry
    response = func()
  File "/home/airflow/.local/lib/python3.7/site-packages/google/resumable_media/requests/upload.py", line 146, in retriable_request
    method, url, data=payload, headers=headers, timeout=timeout
  File "/home/airflow/.local/lib/python3.7/site-packages/google/auth/transport/requests.py", line 545, in request
    self.credentials.before_request(auth_request, method, url, request_headers)
  File "/home/airflow/.local/lib/python3.7/site-packages/google/auth/credentials.py", line 135, in before_request
    self.refresh(request)
  File "/home/airflow/.local/lib/python3.7/site-packages/google/oauth2/service_account.py", line 430, in refresh
    request, self._token_uri, assertion
  File "/home/airflow/.local/lib/python3.7/site-packages/google/oauth2/_client.py", line 300, in jwt_grant
    request, token_uri, body, can_retry=can_retry
  File "/home/airflow/.local/lib/python3.7/site-packages/google/oauth2/_client.py", line 267, in _token_endpoint_request
    **kwargs
  File "/home/airflow/.local/lib/python3.7/site-packages/google/oauth2/_client.py", line 209, in _token_endpoint_request_no_throw
    request_succeeded, response_data, retryable_error = _perform_request()
  File "/home/airflow/.local/lib/python3.7/site-packages/google/oauth2/_client.py", line 186, in _perform_request
    method="POST", url=token_uri, headers=headers, body=body, **kwargs
  File "/home/airflow/.local/lib/python3.7/site-packages/google/auth/transport/requests.py", line 199, in __call__
    six.raise_from(new_exc, caught_exc)
  File "<string>", line 3, in raise_from
google.auth.exceptions.TransportError: ('Connection aborted.', OSError(0, 'Error'))
[2023-06-16T01:01:29.967+0000] {taskinstance.py:1326} INFO - Marking task as UP_FOR_RETRY. dag_id=data_ingestion_gcs_dag, task_id=local_to_gcs_task, execution_date=20230616T010017, start_date=20230616T010129, end_date=20230616T010129
[2023-06-16T01:01:29.991+0000] {standard_task_runner.py:105} ERROR - Failed to execute job 519 for task local_to_gcs_task (('Connection aborted.', OSError(0, 'Error')); 1796)
[2023-06-16T01:01:30.032+0000] {local_task_job.py:212} INFO - Task exited with return code 1
[2023-06-16T01:01:30.057+0000] {taskinstance.py:2585} INFO - 0 downstream tasks scheduled from follow-on schedule check
